Workbook

Sheet DIRETRIZES ORGANIZACIONAIS
A1: Tipo de organização | B1: Startup
A2: Objetivo da Organização | B2: S Dober Insight busca trazer agilidade na criação de Marketing Digital para pequenos negócios.
A3: Propósitos organizacionais | B3: Missão | C3: S Dober busca trazer agilidade na criação de Marketing Digital para pequenos negócios.
B4: Visão de Futuro | C4: S Dober Ser Desenvolvedor em marketing digital nacionalmente de forma que possa estar presente em grandes organizações.
B5: Valores | C5: O princípio da S Dober Insight é a segurança e qualidade do serviço, respeito com o usuários . integridade
A6: Cenários futuros | B6: Desenvolvimento internacional da sturtup

Sheet ANÁLISE DE AMBIENTE - PEST
B1: OPORTUNIDADE | D1: AMEAÇAS
B2: P | C2: Incentivos Governamentais | D2: Instabilidade Política
C3: Acordos Comerciais | D3: Regulações Rigorosas
B4: E | C4: Crescimento Econômico | D4: Recessões Econômicas
C5: Acessibilidade ao Crédito | D5: Inflação Acelerada
B6: S | C6: Mudanças nos Comportamentos do Consumidor | D6: Mudança de Preferências
C7: Maior Inclusão Social | D7: Descontentamento Social
B8: T | C8: Avanços em Tecnologia | D8: Rápida Obsolescência
C9: Adoção Digital | D9: Cibersegurança
B11: P | C11: POLÍTICO
B12: E | C12: ECONÔMICO
B13: S | C13: SOCIAL/CULTURAL/AMBIENTAL
B14: T | C14: TECNOLÓGICA/INOVAÇÃO

Sheet DIAGNÓASTICO ORGANIZACIONAL 
A1: CRITÉRIOS DE PRIORIZAÇÃO | D1: ESPECIFICAÇÃO | E1: GRAVIDADE | F1: URGÊNCIA | G1: TENDÊNCIA | H1: 27
B2: AMBIENTE EXTERNO | C2: OPORTUNIDADES | D2: ='ANÁLISE DE AMBIENTE - PEST'!C2 -> Incentivos Governamentais | E2: 5 | F2: 5 | G2: 3 | H2: =E2*F2*G2 -> 75
D3: ='ANÁLISE DE AMBIENTE - PEST'!C3 -> Acordos Comerciais | E3: 4 | F3: 4 | G3: 3 | H3: =E3*F3*G3 -> 48
D4: ='ANÁLISE DE AMBIENTE - PEST'!C4 -> Crescimento Econômico | E4: 3 | F4: 5 | G4: 2 | H4: =E4*F4*G4 -> 30
D5: ='ANÁLISE DE AMBIENTE - PEST'!C5 -> Acessibilidade ao Crédito | E5: 5 | F5: 2 | G5: 3 | H5: =E5*F5*G5 -> 30
D6: ='ANÁLISE DE AMBIENTE - PEST'!C6 -> Mudanças nos Comportamentos do Consumidor | E6: 2 | F6: 4 | G6: 2 | H6: =E6*F6*G6 -> 16
D7: ='ANÁLISE DE AMBIENTE - PEST'!C7 -> Maior Inclusão Social | E7: 3 | F7: 5 | G7: 4 | H7: =E7*F7*G7 -> 60
D8: ='ANÁLISE DE AMBIENTE - PEST'!C8 -> Avanços em Tecnologia | E8: 3 | F8: 2 | G8: 3 | H8: =E8*F8*G8 -> 18
D9: ='ANÁLISE DE AMBIENTE - PEST'!C9 -> Adoção Digital | E9: 2 | F9: 3 | G9: 3 | H9: =E9*F9*G9 -> 18
C12: AMEAÇAS | D12: ='ANÁLISE DE AMBIENTE - PEST'!D2 -> Instabilidade Política | E12: 4 | F12: 2 | G12: 3 | H12: =E12*F12*G12 -> 24
D13: ='ANÁLISE DE AMBIENTE - PEST'!D3 -> Regulações Rigorosas | E13: 3 | F13: 4 | G13: 3 | H13: =E13*F13*G13 -> 36
D14: ='ANÁLISE DE AMBIENTE - PEST'!D4 -> Recessões Econômicas | E14: 2 | F14: 2 | G14: 4 | H14: =E14*F14*G14 -> 16
D15: ='ANÁLISE DE AMBIENTE - PEST'!D5 -> Inflação Acelerada | E15: 1 | F15: 2 | G15: 4 | H15: =E15*F15*G15 -> 8
D16: ='ANÁLISE DE AMBIENTE - PEST'!D6 -> Mudança de Preferências | E16: 3 | F16: 3 | G16: 3 | H16: =E16*F16*G16 -> 27
D17: ='ANÁLISE DE AMBIENTE - PEST'!D7 -> Descontentamento Social | E17: 2 | F17: 3 | G17: 4 | H17: =E17*F17*G17 -> 24
D18: ='ANÁLISE DE AMBIENTE - PEST'!D8 -> Rápida Obsolescência | E18: 1 | F18: 2 | G18: 4 | H18: =E18*F18*G18 -> 8
D19: ='ANÁLISE DE AMBIENTE - PEST'!D9 -> Cibersegurança | E19: 3 | F19: 3 | G19: 4 | H19: =E19*F19*G19 -> 36
B22: AMBIENTE INTERNO | C22: FORÇAS | D22: Facilidade de Uso | E22: 5 | F22: 4 | G22: 3 | H22: =E22*F22*G22 -> 60
D23: Equipe qualificada | E23: 4 | F23: 4 | G23: 3 | H23: =E23*F23*G23 -> 48
D24: Mobilidade e divercidade de recursos | E24: 4 | F24: 3 | G24: 2 | H24: =E24*F24*G24 -> 24
D25: Personalização de acordo com o cliente | E25: 3 | F25: 3 | G25: 3 | H25: =E25*F25*G25 -> 27
D26: Relacionamento com o cliente | E26: 5 | F26: 5 | G26: 5 | H26: =E26*F26*G26 -> 125
D27: Sustentabilidade | E27: 4 | F27: 3 | G27: 2 | H27: =E27*F27*G27 -> 24
D28: Produto de alto indice de necessidade (produto que todos precisam) | E28: 2 | F28: 3 | G28: 2 | H28: =E28*F28*G28 -> 12
D29: Objetivo bem definido | E29: 5 | F29: 5 | G29: 2 | H29: =E29*F29*G29 -> 50
C32: FRAQUEZAS | D32: A falta de capital | E32: 5 | F32: 3 | G32: 3 | H32: =E32*F32*G32 -> 45
D33: Gerar insights de dados | E33: 4 | F33: 4 | G33: 3 | H33: =E33*F33*G33 -> 48
D34: Ausência de parcerias estrategicas | E34: 3 | F34: 3 | G34: 3 | H34: =E34*F34*G34 -> 27
D35: Falta de suporte tecnico | E35: 5 | F35: 4 | G35: 2 | H35: =E35*F35*G35 -> 40
D36: Falta de Habilidade em Networking | E36: 4 | F36: 4 | G36: 1 | H36: =E36*F36*G36 -> 16
D37: Baixa disponibilidade de desgners | E37: 5 | F37: 4 | G37: 1 | H37: =E37*F37*G37 -> 20
D38: Inovar de forma significativa | E38: 5 | F38: 5 | G38: 2 | H38: =E38*F38*G38 -> 50
D39: Complexidade dos Processos | E39: 4 | F39: 3 | G39: 1 | H39: =E39*F39*G39 -> 12
D40: Facilidade de plagio | E40: 2 | F40: 2 | G40: 5 | H40: =E40*F40*G40 -> 20
D43: Ameaças e Fraquezas: Grave, Urgente, Tendência; Oportunidade: Devemos investir, rápido retorno do investimento, baixo investimento; Força: Reconhecida pelo mercado, ajuda na lucratividade, difícil de imitar;

Sheet 5 FORÇAS DE PORTER
A1: CRITÉRIOS DE PRIORIZAÇÃO | C1: ESPECIFICAÇÃO | D1: GRAVIDADE | E1: URGÊNCIA | F1: TENDÊNCIA | G1: 27
B2: RIVALIDADE ENTRE CONCORRENTES | C2: Custo mudança | D2: 5 | E2: 5 | F2: 5 | G2: =D2*E2*F2 -> 125
C3: Complexidade Informal | D3: 4 | E3: 3 | F3: 3 | G3: =D3*E3*F3 -> 36
C4: Divercidade de concorrencia | D4: 2 | E4: 3 | F4: 2 | G4: =D4*E4*F4 -> 12
C5: Diferança de produto | D5: 5 | E5: 5 | F5: 5 | G5: =D5*E5*F5 -> 125
C6: Custo Fixo | D6: 3 | E6: 3 | F6: 3 | G6: =D6*E6*F6 -> 27
C7: Identidade de marcas | D7: 3 | E7: 2 | F7: 3 | G7: =D7*E7*F7 -> 18
C8: Crescimento da industria | D8: 4 | E8: 3 | F8: 3 | G8: =D8*E8*F8 -> 36
C9: Concentração e equilibrio | D9: 3 | E9: 2 | F9: 2 | G9: =D9*E9*F9 -> 12
G10: =D10*E10*F10 -> 0
G11: =D11*E11*F11 -> 0
B12: AMEAÇA DE NOVOS ENTRANTES | C12: Custo de mudanças | D12: 5 | E12: 5 | F12: 5 | G12: =D12*E12*F12 -> 125
C13: Identidade de marca | D13: 3 | E13: 2 | F13: 3 | G13: =D13*E13*F13 -> 18
C14: Acesso a ensumos necessarios | D14: 4 | E14: 4 | F14: 3 | G14: =D14*E14*F14 -> 48
C15: Vantagem de custo Absoluto | D15: 2 | E15: 3 | F15: 2 | G15: =D15*E15*F15 -> 12
C16: Projeto de produtos de baixo custo | D16: 3 | E16: 2 | F16: 3 | G16: =D16*E16*F16 -> 18
C17: Acesso a distribuição | D17: 3 | E17: 3 | F17: 1 | G17: =D17*E17*F17 -> 9
C18: Retaliação esperada | D18: 3 | E18: 3 | F18: 3 | G18: =D18*E18*F18 -> 27
C19: Economia de escala | D19: 3 | E19: 4 | F19: 3 | G19: =D19*E19*F19 -> 36
G20: =D20*E20*F20 -> 0
G21: =D21*E21*F21 -> 0
B22: PODER DE BARBANHA DOS CLIENTES | C22: Alanvancagem de negociação | D22: 4 | E22: 4 | F22: 5 | G22: =D22*E22*F22 -> 80
C23: Informação do comprador | D23: 4 | E23: 3 | F23: 3 | G23: =D23*E23*F23 -> 36
C24: Produtos substitutos | D24: 2 | E24: 3 | F24: 2 | G24: =D24*E24*F24 -> 12
C25: Volume do comprador | D25: 5 | E25: 4 | F25: 3 | G25: =D25*E25*F25 -> 60
C26: Custo de mudança de comprador versus custo de mudança da empresa | D26: 4 | E26: 4 | F26: 4 | G26: =D26*E26*F26 -> 64
C27: Possibilidade de integração | D27: 2 | E27: 2 | F27: 3 | G27: =D27*E27*F27 -> 12
C28: A reputação da marca | D28: 4 | E28: 4 | F28: 4 | G28: =D28*E28*F28 -> 64
C29: Diferenciais do produto/serviço | D29: 3 | E29: 3 | F29: 3 | G29: =D29*E29*F29 -> 27
G30: =D30*E30*F30 -> 0
G31: =D31*E31*F31 -> 0
B32: PODER DE BARBANHA DOS FORNECEDORES | C32: Diferenciação de insumos | D32: 4 | E32: 3 | F32: 3 | G32: =D32*E32*F32 -> 36
C33: Custo mudança de fornecedores | D33: 3 | E33: 2 | F33: 3 | G33: =D33*E33*F33 -> 18
C34: Presença de insumos substitutos | D34: 4 | E34: 5 | F34: 4 | G34: =D34*E34*F34 -> 80
C35: Concentração de fornecedores | D35: 4 | E35: 3 | F35: 3 | G35: =D35*E35*F35 -> 36
C36: Custo relativo a custo total da industria | D36: 2 | E36: 2 | F36: 2 | G36: =D36*E36*F36 -> 8
C37: Inpacto dos insumos sobre o custo ou diferenciação | D37: 3 | E37: 3 | F37: 3 | G37: =D37*E37*F37 -> 27
C38: Ameaça de integração para frente a relação a ameaça de integração para trás pelas empresas na industria | D38: 1 | E38: 1 | F38: 2 | G38: =D38*E38*F38 -> 2
C39: Inportancia de volume para fornecedor | D39: 3 | E39: 2 | F39: 3 | G39: =D39*E39*F39 -> 18
G40: =D40*E40*F40 -> 0
...

Sheet SWOT
B1: AMBIENTE EXTERNO | L1: OPORTUNIDADES | T1: AMEAÇAS
A2: AMBIENTE INTERNO | G2: OPORTUNIDADES E AMEAÇAS | L2: ='DIAGNÓASTICO ORGANIZACIONAL '!D2 -> Incentivos Governamentais | M2: ='DIAGNÓASTICO ORGANIZACIONAL '!D3 -> Acordos Comerciais | N2: ='DIAGNÓASTICO ORGANIZACIONAL '!D4 -> Crescimento Econômico | O2: ='DIAGNÓASTICO ORGANIZACIONAL '!D5 -> Acessibilidade ao Crédito | P2: ='DIAGNÓASTICO ORGANIZACIONAL '!D6 -> Mudanças nos Comportamentos do Consumidor | Q2: ='DIAGNÓASTICO ORGANIZACIONAL '!D7 -> Maior Inclusão Social | R2: ='DIAGNÓASTICO ORGANIZACIONAL '!D8 -> Avanços em Tecnologia | S2: ='DIAGNÓASTICO ORGANIZACIONAL '!D9 -> Adoção Digital | T2: ='DIAGNÓASTICO ORGANIZACIONAL '!D12 -> Instabilidade Política | U2: ='DIAGNÓASTICO ORGANIZACIONAL '!D13 -> Regulações Rigorosas | V2: ='DIAGNÓASTICO ORGANIZACIONAL '!D14 -> Recessões Econômicas | W2: ='DIAGNÓASTICO ORGANIZACIONAL '!D15 -> Inflação Acelerada | X2: ='DIAGNÓASTICO ORGANIZACIONAL '!D16 -> Mudança de Preferências | Y2: ='DIAGNÓASTICO ORGANIZACIONAL '!D17 -> Descontentamento Social | Z2: ='DIAGNÓASTICO ORGANIZACIONAL '!D18 -> Rápida Obsolescência | AA2: ='DIAGNÓASTICO ORGANIZACIONAL '!D19 -> Cibersegurança | AB2: TOTAL
B7: FORÇAS E FRAQUEZAS
A12: FORÇAS | B12: ='DIAGNÓASTICO ORGANIZACIONAL '!D22 -> Facilidade de Uso | L12: 0 | M12: 0 | N12: 0 | O12: 1 | P12: 1 | Q12: 2 | R12: 2 | S12: 1 | T12: 0 | U12: 0 | V12: 0 | W12: 2 | X12: 0 | Y12: 2 | Z12: 2 | AA12: 2 | AB12: =SUM(L12:AA12) -> 15
B13: ='DIAGNÓASTICO ORGANIZACIONAL '!D23 -> Equipe qualificada | L13: 1 | M13: 1 | N13: 1 | O13: 1 | P13: 2 | Q13: 2 | R13: 2 | S13: 1 | T13: 0 | U13: 0 | V13: 0 | W13: 1 | X13: 2 | Y13: 2 | Z13: 0 | AA13: 1 | AB13: =SUM(L13:AA13) -> 17
B14: ='DIAGNÓASTICO ORGANIZACIONAL '!D25 -> Personalização de acordo com o cliente | L14: 1 | M14: 2 | N14: 1 | O14: 2 | P14: 1 | Q14: 2 | R14: 2 | S14: 1 | T14: 0 | U14: 0 | V14: 1 | W14: 2 | X14: 2 | Y14: 1 | Z14: 2 | AA14: 2 | AB14: =SUM(L14:AA14) -> 22
B15: ='DIAGNÓASTICO ORGANIZACIONAL '!D26 -> Relacionamento com o cliente | L15: 1 | M15: 1 | N15: 1 | O15: 2 | P15: 2 | Q15: 1 | R15: 2 | S15: 1 | T15: 1 | U15: 0 | V15: 1 | W15: 2 | X15: 2 | Y15: 2 | Z15: 0 | AA15: 2 | AB15: =SUM(L15:AA15) -> 21
B16: ='DIAGNÓASTICO ORGANIZACIONAL '!D27 -> Sustentabilidade | L16: 2 | M16: 2 | N16: 1 | O16: 1 | P16: 1 | Q16: 0 | R16: 2 | S16: 1 | T16: 2 | U16: 2 | V16: 1 | W16: 2 | X16: 0 | Y16: 2 | Z16: 2 | AA16: 2 | AB16: =SUM(L16:AA16) -> 23
A17: FRAQUEZAS | B17: ='DIAGNÓASTICO ORGANIZACIONAL '!D32 -> A falta de capital | L17: 1 | M17: 1 | N17: 2 | O17: 2 | P17: 0 | Q17: 0 | R17: 2 | S17: 0 | T17: 0 | U17: 0 | V17: 2 | W17: 2 | X17: 1 | Y17: 0 | Z17: 1 | AA17: 1 | AB17: =SUM(L17:AA17) -> 15
B18: ='DIAGNÓASTICO ORGANIZACIONAL '!D37 -> Baixa disponibilidade de desgners | L18: 2 | M18: 2 | N18: 0 | O18: 0 | P18: 2 | Q18: 2 | R18: 2 | S18: 0 | T18: 0 | U18: 1 | V18: 1 | W18: 1 | X18: 1 | Y18: 0 | Z18: 2 | AA18: 1 | AB18: =SUM(L18:AA18) -> 17
B19: ='DIAGNÓASTICO ORGANIZACIONAL '!D38 -> Inovar de forma significativa | L19: 0 | M19: 2 | N19: 1 | O19: 2 | P19: 2 | Q19: 0 | R19: 0 | S19: 2 | T19: 0 | U19: 2 | V19: 2 | W19: 0 | X19: 0 | Y19: 0 | Z19: 2 | AA19: 1 | AB19: =SUM(L19:AA19) -> 16
B20: ='DIAGNÓASTICO ORGANIZACIONAL '!D39 -> Complexidade dos Processos | L20: 2 | M20: 0 | N20: 0 | O20: 0 | P20: 2 | Q20: 0 | R20: 2 | S20: 2 | T20: 0 | U20: 1 | V20: 2 | W20: 2 | X20: 2 | Y20: 1 | Z20: 2 | AA20: 1 | AB20: =SUM(L20:AA20) -> 19
B21: ='DIAGNÓASTICO ORGANIZACIONAL '!D40 -> Facilidade de plagio | L21: 0 | M21: 0 | N21: 0 | O21: 0 | P21: 2 | Q21: 1 | R21: 2 | S21: 0 | T21: 0 | U21: 0 | V21: 0 | W21: 0 | X21: 1 | Y21: 1 | Z21: 2 | AA21: 1 | AB21: =SUM(L21:AA21) -> 10
B22: TOTAL | L22: =SUM(L12:L21) -> 10 | M22: =SUM(M12:M21) -> 11 | N22: =SUM(N12:N21) -> 7 | O22: =SUM(O12:O21) -> 11 | P22: =SUM(P12:P21) -> 15 | Q22: =SUM(Q12:Q21) -> 10 | R22: =SUM(R12:R21) -> 18 | S22: =SUM(S12:S21) -> 9 | ... AB22: =SUM(AB12:AB21) -> 175
B23: Capacidade Ofensiva (QI - QIII) = | P23: =T24-T25 -> 11
B24: Capacidade Defensiva (QII - QIV) = | P24: =U24-U25 -> 10 | T24: =SUM(L12:S16) -> 51 | U24: =SUM(T12:AA16) -> 47 | X24: =T24/AB22 -> 0.29142857 | Y24: =U24/AB22 -> 0.26857143
B25: Posicionamento Estratégico = | P25: =SUM(P23:P24) -> 21 | T25: =SUM(L17:S21) -> 40 | U25: =SUM(T17:AA21) -> 37 | X25: =T25/AB22 -> 0.22857143 | Y25: =U25/AB22 -> 0.21142857

Sheet PLANO DE AÇÃO - 5W2H
A1: PLANO DE AÇÃO ESTRATÉGICA
A5: OBJETIVO ESTRATÉGIVO | B5: O QUE FAZER | C5: Como | D5: Quem | E5: Quando | F5: Onde | G5: Porque | H5: Como será medido | I5: Observação | L5: Status
B6: Metas específicas | C6: (Estratégias) | D6: (Responsável) | E6: (Prazo / conclusão) | F6: Local | G6: Justificativa | H6: Crie um indicador | I6: ( análise de eficácia) | L6: Apresentação do andamento do plano de ação
A7: 1.AUMENTAR A EQUIPE DE DESGNERS | B7: Aumento de beneficios para novos contratados | C7: Programa de bem-estar e flexibilidade | D7: Diretor de Operações | E7: 2 a 3 meses | F7: Empresa | G7: Qualidade de vida | H7: Feedback funcionarios | I7: Coleta de Dados | J7: Interpretação dos Resultados | K7: Relatório e Recomendações | L7: EM DESENVOLVIMENTO
B8: Desenvolver a equipe de Desgners (Para que não aja baixas) | C8: Oportunidade de crescimento | D8: Disner Senior | E8: 1 a 4 meses | F8: Empresa | G8: Qualidade de vida | H8: Feedback funcionarios | I8: Coleta de Dados | J8: Interpretação dos Resultados | K8: Relatório e Recomendações | L8: EM DESENVOLVIMENTO
B9: Contratação de 3º | C9: Pesquisa de Mercado | D9: Diretor de Operações | E9: 1 a 2 meses | F9: WebSites | G9: Aumento de capacidade | H9: Feedback Clientes | I9: Coleta de Dados | J9: Interpretação dos Resultados | K9: Relatório e Recomendações | L9: EM DESENVOLVIMENTO
A10: 2. INOVAR DE FORMA SIGNFICATIVA | B10: Buscar por inovações no exterior | C10: Pesquisa de Mercado | D10: Diretor de Operações | E10: 4 a 5 meses | F10: WebSites | G10: Qualidade de Informação | H10: Feedback funcionarios | I10: Coleta de Dados | J10: Interpretação dos Resultados | K10: Relatório e Recomendações | L10: EM DESENVOLVIMENTO
B11: Manter software´s atualizados | C11: Forum's de tecnologia | D11: Desenvolvedores de Software (Equipe) | E11: 1 ano | F11: WebSites | G11: Velocidade de produção | H11: Controle finaceiro | I11: Análise dos Dados | J11: Interpretação dos Resultados | K11: Relatório e Recomendações | L11: EM DESENVOLVIMENTO
B12: Resolver bug's do sistema com novas tecnologias | C12: Forum's de tecnologia | D12: Suporte Técnico (Equipe) | E12: 1 a 2 anos | F12: WebSites | G12: Velocidade de produção | H12: Controle finaceiro | I12: Análise dos Dados | J12: Interpretação dos Resultados | K12: Relatório e Recomendações | L12: EM DESENVOLVIMENTO
A13: 3. MELHORIA DOS PROCESSOS INTERNOS | B13: Realizar um mapeamento detalhado de todos os processos | C13: Mapeamento de Processos | D13: Diretor de Operações | E13: 2 a 3 meses | F13: Empresa | G13: Organização | H13: Feedback funcionarios | I13: Análise dos Dados | J13: Interpretação dos Resultados | K13: Relatório e Recomendações | L13: EM DESENVOLVIMENTO
B14: Implementar soluções de automação para ao menos 30% das atividades | C14: Implementar ferramentasIntercom, Drift, Zendesk Chat | D14: Suporte Técnico (Equipe) | E14: 6 meses a 1 ano | F14: WebSites | G14: Segurança de informação | H14: Controle finaceiro | I14: Análise dos Dados | J14: Interpretação dos Resultados | K14: Relatório e Recomendações | L14: EM DESENVOLVIMENTO
B15: Revisar e simplificar os processos principais | C15: 5S, Kanban e PDCA | D15: Diretor de Operações | E15: 3 a 6 meses | F15: Empresa | G15: Qualidade de Informação | H15: Feedback funcionarios | I15: Análise dos Dados | J15: Interpretação dos Resultados | K15: Relatório e Recomendações | L15: EM DESENVOLVIMENTO
A16: 4. IMPLEMENTAÇÕES DE AÇÕES PARA MINIMIZAR OS IMPACTOS INFLACIONÁRIOS | B16: Reduzir os custos operacionais em 15% nos próximos 12 meses | C16: Pesquisa de Mercado | D16: Diretor de Operações | E16: 12 meses | F16: Empresa | G16: Organização | H16: Controle finaceiro | I16: Análise dos Dados | J16: Interpretação dos Resultados | K16: Relatório e Recomendações | L16: EM DESENVOLVIMENTO
B17: Aumentar em 10% as receitas através de reajuste de preços | C17: Pesquisa de Mercado | D17: Social midia | E17: 6 meses | F17: Empresa | G17: Organização | H17: Controle finaceiro | I17: Análise dos Dados | J17: Interpretação dos Resultados | K17: Relatório e Recomendações | L17: EM DESENVOLVIMENTO
B18: Aumentar a retenção de clientes em 20% por meio de programas | C18: Pesquisa de Mercado | D18: Social midia | E18: 12 meses | F18: WebSites | G18: Organização | H18: Controle finaceiro | I18: Análise dos Dados | J18: Interpretação dos Resultados | K18: Relatório e Recomendações | L18: EM DESENVOLVIMENTO
A19: 5. IMPLEMENTAÇÕES DE AÇÕES PARA CAPTAR NOVOS CLIENTES E FIDELIZAR OS CLIENTES EXISTENTES | B19: Aumentar a taxa de conversão de novos clientes em 30% | C19: Oportunidade de crescimento | D19: Social midia | E19: 12 meses | F19: empresa | G19: Organização | H19: Controle finaceiro | I19: Análise dos Dados | J19: Interpretação dos Resultados | K19: Relatório e Recomendações | L19: EM DESENVOLVIMENTO
B20: Aumentar a retenção de clientes em 40% em 18 meses | C20: Pesquisa de Mercado | D20: Diretor de Operações | E20: 18 meses | F20: empresa | G20: Organização | H20: Controle finaceiro | I20: Análise dos Dados | J20: Interpretação dos Resultados | K20: Relatório e Recomendações | L20: EM DESENVOLVIMENTO
B21: Expandir a presença da marca em 50% em redes sociais | C21: Oportunidade de crescimento | D21: Social midia | E21: 9 meses | F21: Campanhas online | G21: Organização | H21: Controle finaceiro | I21: Coleta de Dados | J21: Interpretação dos Resultados | K21: Relatório e Recomendações | L21: EM DESENVOLVIMENTO
A22: 6. IMPLEMENTAR AÇÕES PARA DIMINUIR O DESCONTENTAMENTO SOCIAL | B22: participação da empresa em projetos comunitários | C22: Oportunidade de crescimento | D22: Diretor de Operações e Social Midia | E22: 12 meses | F22: empresa | G22: Organização | H22: Controle finaceiro | I22: Análise dos Dados | J22: Interpretação dos Resultados | K22: Relatório e Recomendações | L22: EM DESENVOLVIMENTO
B23: Promover três campanhas de conscientização sobre questões sociais | C23: Pesquisa de Mercado | D23: Social midia | E23: 12 meses | F23: Plataformas digitais | G23: Organização | H23: Controle finaceiro | I23: Análise dos Dados | J23: Interpretação dos Resultados | K23: Relatório e Recomendações | L23: EM DESENVOLVIMENTO
B24: Realizar uma pesquisa de satisfação e percepção comunitária | C24: Forum's de tecnologia | D24: Comunicação | E24: 6 meses | F24: Comunidade local | G24: Qualidade de Informação | H24: Feedback | I24: Análise dos Dados | J24: Interpretação dos Resultados | K24: Relatório e Recomendações | L24: EM DESENVOLVIMENTO
A25: 7. IMPLEMENTAR AÇÕES PARA QUALIFICAR A EQUIPE DE DESENVOLVIMENTO | B25: Apoiar e insentivar a obtenção de certificados profissionais | C25: Oportunidade de crescimento | D25: Diretor de Operações | E25: cada 6 meses | F25: empresa | G25: Organização | H25: Controle | I25: Análise dos Dados | J25: Interpretação dos Resultados | K25: Relatório e Recomendações | L25: EM DESENVOLVIMENTO
B26: Promover Treinamento técnicos periódicos | C26: Oportunidade de crescimento | D26: Diretor de Operações | E26: 2 meses | F26: empresa | G26: Organização | H26: Controle | I26: Análise dos Dados | J26: Interpretação dos Resultados | K26: Relatório e Recomendações | L26: EM DESENVOLVIMENTO
B27: Estabelecer um programa de mentoria | C27: Oportunidade de crescimento | D27: Diretor de Operações | E27: 4 meses | F27: empresa | G27: Organização | H27: Feedback | I27: Análise dos Dados | J27: Interpretação dos Resultados | K27: Relatório e Recomendações | L27: EM DESENVOLVIMENTO
A28: 8. CIBERSEGURANÇA | B28: Implementar MFA (Autenticação Multifatorial) para Todos os Usuários | C28: Programa de qualificação interna | D28: Diretor de Operações | E28: 6 a 1 ano | F28: empresa | G28: Organização | H28: Feedback | I28: Análise dos Dados | J28: Interpretação dos Resultados | K28: Relatório e Recomendações | L28: EM DESENVOLVIMENTO
B29: Realizar Avaliações de Segurança Mensais | C29: kanban | D29: Diretor de Operações e Social Midia | E29: 1 mes | F29: empresa | G29: Organização | H29: Feedback | I29: Análise dos Dados | J29: Interpretação dos Resultados | K29: Relatório e Recomendações | L29: EM DESENVOLVIMENTO
B30: Treinamento em Cibersegurança para os Funcionários | C30: Programa de qualificação interna | D30: Diretor de Operações e Social Midia | E30: 2 meses | F30: empresa | G30: Organização | H30: Feedback | I30: Análise dos Dados | J30: Interpretação dos Resultados | K30: Relatório e Recomendações | L30: EM DESENVOLVIMENTO
A37: 1. OBJETIVO
A40: 1. OBJETIVO
A43: 1. OBJETIVO
A46: 1. OBJETIVO
A49: 1. OBJETIVO
A52: 1. OBJETIVO
A55: 1. OBJETIVO
A58: 1. OBJETIVO
